<?xml version="1.0" ?>
<!-- =================================================================================== -->
<!-- |    This document was autogenerated by xacro from robot.urdf.xacro               | -->
<!-- |    EDITING THIS FILE BY HAND IS NOT RECOMMENDED                                 | -->
<!-- =================================================================================== -->
<robot name="lwa4p" xmlns:controller="http://playerstage.sourceforge.net/gazebo/xmlschema/#controller" xmlns:interface="http://playerstage.sourceforge.net/gazebo/xmlschema/#interface" xmlns:sensor="http://playerstage.sourceforge.net/gazebo/xmlschema/#sensor" xmlns:xacro="http://ros.org/wiki/xacro">
  <material name="Schunk/LightGrey">
    <color rgba="0.7 0.7 0.7 1.0"/>
  </material>
  <material name="Schunk/DarkGrey">
    <color rgba="0.4 0.4 0.4 1.0"/>
  </material>
  <material name="Schunk/Black">
    <color rgba="0.0 0.0 0.0 1.0"/>
  </material>
  <material name="Schunk/DarkGolden">
    <color rgba="0.4 0.4 0.3 1.0"/>
  </material>
  <material name="Schunk/Blue">
    <color rgba="0.0 0.0 0.8 1.0"/>
  </material>
  <!-- zed camera -->
  <!--  <xacro:include filename="$(find zed_wrapper)/urdf/zed.urdf"/>-->
  <!-- Used for fixing robot to Gazebo -->
  <link name="world"/>
  <link name="body">
    <origin rpy="0 0 0" xyz="0 0 0"/>
    <collision>
      <!--      <origin xyz=".7 .7 -1.33" rpy="1.5707 0 -1.5707"/>-->
      <!--      <geometry>-->
      <!--        <mesh filename="package://schunk_lwa4p_svh/description/meshes/humanoid/chestconvexhull.stl" scale="0.001 0.001 0.001"/>-->
      <!--      </geometry>-->
      <origin rpy="0 0 0" xyz="-0.03 -.046 -0.038"/>
      <geometry>
        <box size=".4 .525 .576"/>
      </geometry>
    </collision>
    <visual>
      <origin rpy="1.5707 0 -1.5707" xyz=".7 .7 -1.33"/>
      <geometry>
        <mesh filename="package://grasping_sim/urdf/meshes/humanoid/chestlowres.stl" scale="0.001 0.001 0.001"/>
      </geometry>
    </visual>
  </link>
  <link name="head">
    <origin rpy="0 0 0" xyz="0 0 0"/>
    <collision>
      <geometry>
        <mesh filename="package://grasping_sim/urdf/meshes/humanoid/headconvexhull.stl" scale="0.001 0.001 0.001"/>
      </geometry>
    </collision>
    <visual>
      <geometry>
        <mesh filename="package://grasping_sim/urdf/meshes/humanoid/headlowres.stl" scale="0.001 0.001 0.001"/>
      </geometry>
    </visual>
  </link>
  <joint name="head_neck" type="fixed">
    <parent link="body"/>
    <child link="head"/>
    <origin rpy="0.4887 0 -1.5707" xyz=".27 .11 -.67"/>
  </joint>
  <!-- joint between base_link and lwa4p_extended_connector_link -->
  <joint name="arm_podest_joint" type="fixed">
    <origin rpy="1.5707 0 0" xyz="0 -0.27 0.08"/>
    <parent link="body"/>
    <child link="arm_podest_link"/>
  </joint>
  <link name="arm_podest_link">
    <inertial>
      <mass value="0.01"/>
      <origin xyz="0 0 0"/>
      <inertia ixx="0.001" ixy="0.0" ixz="0.0" iyy="0.001" iyz="0.0" izz="0.001"/>
    </inertial>
    <visual>
      <origin rpy="0 3.14159265359 0" xyz="0 0 0"/>
      <geometry>
        <mesh filename="package://grasping_sim/urdf/meshes/lwa4p/arm_base_link.stl"/>
      </geometry>
    </visual>
    <collision>
      <origin rpy="0 3.14159265359 0" xyz="0 0 0"/>
      <geometry>
        <mesh filename="package://grasping_sim/urdf/meshes/lwa4p/arm_base_link.stl"/>
      </geometry>
    </collision>
  </link>
  <joint name="arm_base_joint" type="fixed">
    <origin rpy="0 0 0" xyz="0 0 0.10"/>
    <parent link="arm_podest_link"/>
    <child link="arm_base_link"/>
  </joint>
  <link name="arm_base_link">
    <inertial>
      <mass value="0.01"/>
      <origin xyz="0 0 0"/>
      <inertia ixx="0.001" ixy="0.0" ixz="0.0" iyy="0.001" iyz="0.0" izz="0.001"/>
    </inertial>
  </link>
  <!-- joint between arm_0_link and arm_1_link -->
  <joint name="arm_1_joint" type="revolute">
    <origin rpy="0 0 0" xyz="0 0 0"/>
    <parent link="arm_base_link"/>
    <child link="arm_1_link"/>
    <axis xyz="0 0 1"/>
    <limit effort="370" lower="-2.947" upper="2.947" velocity="1.26"/>
    <!--safety_controller k_position="20" k_velocity="50" soft_lower_limit="${-6.28 + 0.01}" soft_upper_limit="${6.28 - 0.01}" /-->
  </joint>
  <link name="arm_1_link">
    <inertial>
      <mass value="0.01"/>
      <origin xyz="0 0 0"/>
      <inertia ixx="0.001" ixy="0.0" ixz="0.0" iyy="0.001" iyz="0.0" izz="0.001"/>
    </inertial>
    <!--
      <inertial>
        <origin xyz="0 0 0" rpy="0 0 0" />
        <mass value="0.29364"/>
        <inertia ixx="0.01" ixy="0" ixz="0" iyy="0.01" iyz="0" izz="0.01" />
      </inertial>
-->
    <visual>
      <origin rpy="0 0 0" xyz="0 0 0"/>
      <geometry>
        <mesh filename="package://grasping_sim/urdf/meshes/lwa4p/arm_1_link.stl"/>
      </geometry>
      <material name="Schunk/Blue"/>
    </visual>
    <collision>
      <origin rpy="0 0 0" xyz="0 0 0"/>
      <geometry>
        <mesh filename="package://grasping_sim/urdf/meshes/lwa4p/arm_1_link.stl"/>
      </geometry>
    </collision>
  </link>
  <!-- joint between arm_1_link and arm_2_link -->
  <joint name="arm_2_joint" type="revolute">
    <origin rpy="1.5708 0 0" xyz="0 0 0"/>
    <parent link="arm_1_link"/>
    <child link="arm_2_link"/>
    <axis xyz="0 0 1"/>
    <limit effort="370" lower="-2.947" upper="2.947" velocity="1.26"/>
    <!--safety_controller k_position="20" k_velocity="50" soft_lower_limit="${-2.09 + 0.01}" soft_upper_limit="${2.09 - 0.01}" /-->
  </joint>
  <link name="arm_2_link">
    <inertial>
      <mass value="0.01"/>
      <origin xyz="0 0 0"/>
      <inertia ixx="0.001" ixy="0.0" ixz="0.0" iyy="0.001" iyz="0.0" izz="0.001"/>
    </inertial>
    <!--
      <inertial>
        <origin xyz="0 0 0" rpy="0 0 0"/>
        <mass value="1.68311"/>
        <inertia ixx="0.03" ixy="0" ixz="0" iyy="0.03" iyz="0" izz="0.03" />
      </inertial>
-->
    <visual>
      <origin rpy="0 0 0" xyz="0 0 0"/>
      <geometry>
        <mesh filename="package://grasping_sim/urdf/meshes/lwa4p/arm_2_link.stl"/>
      </geometry>
      <material name="Schunk/LightGrey"/>
    </visual>
    <collision>
      <origin rpy="0 0 0" xyz="0 0 0"/>
      <geometry>
        <mesh filename="package://grasping_sim/urdf/meshes/lwa4p/arm_2_link.stl"/>
      </geometry>
    </collision>
  </link>
  <!-- joint between arm_2_link and arm_3_link -->
  <joint name="arm_3_joint" type="revolute">
    <origin rpy="0 3.14159 0" xyz="0 0.350 0"/>
    <parent link="arm_2_link"/>
    <child link="arm_3_link"/>
    <axis xyz="0 0 1"/>
    <limit effort="176" lower="-2.694" upper="2.694" velocity="1.26"/>
    <!--safety_controller k_position="20" k_velocity="25" soft_lower_limit="${-6.28 + 0.01}" soft_upper_limit="${6.28 - 0.01}" /-->
  </joint>
  <link name="arm_3_link">
    <inertial>
      <mass value="0.01"/>
      <origin xyz="0 0 0"/>
      <inertia ixx="0.001" ixy="0.0" ixz="0.0" iyy="0.001" iyz="0.0" izz="0.001"/>
    </inertial>
    <!--
      <inertial>
        <origin xyz="0 0 0" rpy="0 0 0"/>
        <mass value="2.1"/>
        <inertia ixx="0.03" ixy="0" ixz="0" iyy="0.03" iyz="0" izz="0.03" />
      </inertial>
-->
    <visual>
      <origin rpy="0 0 0" xyz="0 0 0"/>
      <geometry>
        <mesh filename="package://grasping_sim/urdf/meshes/lwa4p/arm_3_link.stl"/>
      </geometry>
      <material name="Schunk/Blue"/>
    </visual>
    <collision>
      <origin rpy="0 0 0" xyz="0 0 0"/>
      <geometry>
        <mesh filename="package://grasping_sim/urdf/meshes/lwa4p/arm_3_link.stl"/>
      </geometry>
    </collision>
  </link>
  <!-- joint between arm_3_link and arm_4_link -->
  <joint name="arm_4_joint" type="revolute">
    <origin rpy="-1.5708 3.14159 0" xyz="0 0 0"/>
    <parent link="arm_3_link"/>
    <child link="arm_4_link"/>
    <axis xyz="0 0 1"/>
    <limit effort="176" lower="-2.947" upper="2.947" velocity="1.26"/>
    <!--safety_controller k_position="20" k_velocity="25" soft_lower_limit="${-2.09 + 0.01}" soft_upper_limit="${2.09 - 0.01}" /-->
  </joint>
  <link name="arm_4_link">
    <inertial>
      <mass value="0.01"/>
      <origin xyz="0 0 0"/>
      <inertia ixx="0.001" ixy="0.0" ixz="0.0" iyy="0.001" iyz="0.0" izz="0.001"/>
    </inertial>
    <!--
      <inertial>
        <origin xyz="0 0 0" rpy="0 0 0"/>
        <mass value="1.68311"/>
        <inertia ixx="0.03" ixy="0" ixz="0" iyy="0.03" iyz="0" izz="0.03" />
      </inertial>
-->
    <visual>
      <origin rpy="0 0 0" xyz="0 0 0"/>
      <geometry>
        <mesh filename="package://grasping_sim/urdf/meshes/lwa4p/arm_4_link.stl"/>
      </geometry>
      <material name="Schunk/LightGrey"/>
    </visual>
    <collision>
      <origin rpy="0 0 0" xyz="0 0 0"/>
      <geometry>
        <mesh filename="package://grasping_sim/urdf/meshes/lwa4p/arm_4_link.stl"/>
      </geometry>
    </collision>
  </link>
  <!-- joint between arm_4_link and arm_5_link -->
  <joint name="arm_5_joint" type="revolute">
    <origin rpy="1.5708 0 3.14159" xyz="0 0.005263 0.305"/>
    <parent link="arm_4_link"/>
    <child link="arm_5_link"/>
    <axis xyz="0 0 1"/>
    <limit effort="41.6" lower="-2.947" upper="2.947" velocity="1.26"/>
    <!--safety_controller k_position="20" k_velocity="25" soft_lower_limit="${-6.28 + 0.01}" soft_upper_limit="${6.28 - 0.01}" /-->
  </joint>
  <link name="arm_5_link">
    <inertial>
      <mass value="0.01"/>
      <origin xyz="0 0 0"/>
      <inertia ixx="0.001" ixy="0.0" ixz="0.0" iyy="0.001" iyz="0.0" izz="0.001"/>
    </inertial>
    <!--
      <inertial>
        <origin xyz="0 0 0" rpy="0 0 0"/>
        <mass value="0.807"/>
        <inertia ixx="0.03" ixy="0" ixz="0" iyy="0.03" iyz="0" izz="0.03" />
      </inertial>
-->
    <visual>
      <origin rpy="0 0 0" xyz="0 0 0"/>
      <geometry>
        <mesh filename="package://grasping_sim/urdf/meshes/lwa4p/arm_5_link.stl"/>
      </geometry>
      <material name="Schunk/Blue"/>
    </visual>
    <collision>
      <origin rpy="0 0 0" xyz="0 0 0"/>
      <geometry>
        <mesh filename="package://grasping_sim/urdf/meshes/lwa4p/arm_5_link.stl"/>
      </geometry>
    </collision>
  </link>
  <!-- joint between arm_5_link and arm_6_link -->
  <joint name="arm_6_joint" type="revolute">
    <origin rpy="-1.5708 0 0" xyz="0 0 0"/>
    <parent link="arm_5_link"/>
    <child link="arm_6_link"/>
    <axis xyz="0 0 1"/>
    <limit effort="20.1" lower="-2.947" upper="2.947" velocity="1.26"/>
    <!--safety_controller k_position="20" k_velocity="25" soft_lower_limit="${-2.09 + 0.01}" soft_upper_limit="${2.09 - 0.01}" /-->
  </joint>
  <link name="arm_6_link">
    <inertial>
      <mass value="0.01"/>
      <origin xyz="0 0 0"/>
      <inertia ixx="0.001" ixy="0.0" ixz="0.0" iyy="0.001" iyz="0.0" izz="0.001"/>
    </inertial>
    <!--
      <inertial>
        <origin xyz="0 0 0" rpy="0 0 0"/>
        <mass value="0.819"/>
        <inertia ixx="0.01" ixy="0" ixz="0" iyy="0.01" iyz="0" izz="0.01" />
      </inertial>
-->
    <visual>
      <origin rpy="0 0 0" xyz="0 0 0"/>
      <geometry>
        <mesh filename="package://grasping_sim/urdf/meshes/lwa4p/arm_6_link.stl"/>
      </geometry>
      <material name="Schunk/LightGrey"/>
    </visual>
    <collision>
      <origin rpy="0 0 0" xyz="0 0 0"/>
      <geometry>
        <mesh filename="package://grasping_sim/urdf/meshes/lwa4p/arm_6_link.stl"/>
      </geometry>
    </collision>
  </link>
  <gazebo reference="arm_0_link">
    <gravity>true</gravity>
    <self_collide>false</self_collide>
    <material value="Gazebo/LightGrey"/>
  </gazebo>
  <gazebo reference="arm_1_link">
    <gravity>true</gravity>
    <self_collide>false</self_collide>
    <material value="Gazebo/Blue"/>
  </gazebo>
  <gazebo reference="arm_2_link">
    <gravity>true</gravity>
    <self_collide>false</self_collide>
    <material value="Gazebo/LightGrey"/>
  </gazebo>
  <gazebo reference="arm_3_link">
    <gravity>true</gravity>
    <self_collide>false</self_collide>
    <material value="Gazebo/Blue"/>
  </gazebo>
  <gazebo reference="arm_4_link">
    <gravity>true</gravity>
    <self_collide>false</self_collide>
    <material value="Gazebo/LightGrey"/>
  </gazebo>
  <gazebo reference="arm_5_link">
    <gravity>true</gravity>
    <self_collide>false</self_collide>
    <material value="Gazebo/Blue"/>
  </gazebo>
  <gazebo reference="arm_6_link">
    <gravity>true</gravity>
    <self_collide>false</self_collide>
    <material value="Gazebo/LightGrey"/>
  </gazebo>
  <transmission name="arm_1_trans">
    <type>transmission_interface/SimpleTransmission</type>
    <joint name="arm_1_joint">
      <hardwareInterface>PositionJointInterface</hardwareInterface>
      <hardwareInterface>VelocityJointInterface</hardwareInterface>
      <hardwareInterface>EffortJointInterface</hardwareInterface>
    </joint>
    <actuator name="arm_1_motor">
      <mechanicalReduction>1</mechanicalReduction>
    </actuator>
  </transmission>
  <transmission name="arm_2_trans">
    <type>transmission_interface/SimpleTransmission</type>
    <joint name="arm_2_joint">
      <hardwareInterface>PositionJointInterface</hardwareInterface>
      <hardwareInterface>VelocityJointInterface</hardwareInterface>
      <hardwareInterface>EffortJointInterface</hardwareInterface>
    </joint>
    <actuator name="arm_2_motor">
      <mechanicalReduction>1</mechanicalReduction>
    </actuator>
  </transmission>
  <transmission name="arm_3_trans">
    <type>transmission_interface/SimpleTransmission</type>
    <joint name="arm_3_joint">
      <hardwareInterface>PositionJointInterface</hardwareInterface>
      <hardwareInterface>VelocityJointInterface</hardwareInterface>
      <hardwareInterface>EffortJointInterface</hardwareInterface>
    </joint>
    <actuator name="arm_3_motor">
      <mechanicalReduction>1</mechanicalReduction>
    </actuator>
  </transmission>
  <transmission name="arm_4_trans">
    <type>transmission_interface/SimpleTransmission</type>
    <joint name="arm_4_joint">
      <hardwareInterface>PositionJointInterface</hardwareInterface>
      <hardwareInterface>VelocityJointInterface</hardwareInterface>
      <hardwareInterface>EffortJointInterface</hardwareInterface>
    </joint>
    <actuator name="arm_4_motor">
      <mechanicalReduction>1</mechanicalReduction>
    </actuator>
  </transmission>
  <transmission name="arm_5_trans">
    <type>transmission_interface/SimpleTransmission</type>
    <joint name="arm_5_joint">
      <hardwareInterface>PositionJointInterface</hardwareInterface>
      <hardwareInterface>VelocityJointInterface</hardwareInterface>
      <hardwareInterface>EffortJointInterface</hardwareInterface>
    </joint>
    <actuator name="arm_5_motor">
      <mechanicalReduction>1</mechanicalReduction>
    </actuator>
  </transmission>
  <transmission name="arm_6_trans">
    <type>transmission_interface/SimpleTransmission</type>
    <joint name="arm_6_joint">
      <hardwareInterface>PositionJointInterface</hardwareInterface>
      <hardwareInterface>VelocityJointInterface</hardwareInterface>
      <hardwareInterface>EffortJointInterface</hardwareInterface>
    </joint>
    <actuator name="arm_6_motor">
      <mechanicalReduction>1</mechanicalReduction>
    </actuator>
  </transmission>
  <!-- ros_control plugin -->
  <gazebo>
    <plugin filename="libhwi_switch_gazebo_ros_control.so" name="ros_control">
      <robotNamespace>arm</robotNamespace>
      <filterJointsParam>joint_names</filterJointsParam>
    </plugin>
  </gazebo>
  <!-- RIGHT HAND = 1, LEFT HAND = -1 -->
  <!-- BASE_LINE LINKS -->
  <joint name="left_hand_base_joint" type="fixed">
    <origin rpy="0 0 0" xyz="0 0 .1"/>
    <parent link="arm_6_link"/>
    <child link="left_hand_base_link"/>
  </joint>
  <link name="left_hand_base_link">
    <origin rpy="0 0 0" xyz="0 0 .1"/>
    <visual>
      <origin rpy="0 0 0" xyz="0 0 -0.032"/>
      <geometry>
        <mesh filename="package://schunk_lwa4p_svh/description/meshes/svh/base10.dae"/>
      </geometry>
    </visual>
    <collision>
      <origin rpy="0 0 0" xyz="0 0 -0.032"/>
      <geometry>
        <mesh filename="package://schunk_lwa4p_svh/description/meshes/svh/base10.dae"/>
      </geometry>
    </collision>
  </link>
  <link name="left_hand_d">
    <visual>
      <geometry>
        <cylinder length="0.110" radius="0.001"/>
      </geometry>
      <material name="left_hand_green"/>
    </visual>
  </link>
  <link name="left_hand_h">
    <visual>
      <origin rpy="0 1.571 0" xyz="0.0125 0 0.0825"/>
      <geometry>
        <cylinder length="0.025" radius="0.001"/>
      </geometry>
      <material name="left_hand_green"/>
    </visual>
  </link>
  <link name="left_hand_d2">
    <visual>
      <origin rpy="0 0 0" xyz="0.025 0 0.09625"/>
      <geometry>
        <cylinder length="0.0275" radius="0.001"/>
      </geometry>
      <material name="left_hand_green"/>
    </visual>
  </link>
  <!-- LENGTH NOT FOUND IN DATASHEET! GUESSED!!! -->
  <link name="left_hand_e1">
    <visual>
      <origin rpy="0 0 0" xyz="0 0.01313 0"/>
      <geometry>
        <mesh filename="package://schunk_lwa4p_svh/description/meshes/svh/h10.dae" scale="-1 1 1"/>
      </geometry>
    </visual>
    <collision>
      <origin rpy="0 0 0" xyz="0 0.01313 0"/>
      <geometry>
        <mesh filename="package://schunk_lwa4p_svh/description/meshes/svh/h10.dae" scale="-1 1 1"/>
      </geometry>
    </collision>
  </link>
  <!-- LENGTH NOT FOUND IN DATASHEET! GUESSED!!! -->
  <link name="left_hand_e2">
    <visual>
      <origin xyz="0.0007 0 -0.01002"/>
      <geometry>
        <mesh filename="package://schunk_lwa4p_svh/description/meshes/svh/h11.dae" scale="-1 1 1"/>
      </geometry>
    </visual>
    <collision>
      <origin xyz="0.0007 0 -0.01002"/>
      <geometry>
        <mesh filename="package://schunk_lwa4p_svh/description/meshes/svh/h11.dae" scale="-1 1 1"/>
      </geometry>
    </collision>
  </link>
  <!-- LENGTH NOT FOUND IN DATASHEET! GUESSED!!! -->
  <link name="left_hand_e3">
    <!-- <visual> -->
    <!-- 	<origin rpy="0 0 0" xyz="${side*(0.0175)} 0 0.015" /> -->
    <!-- 	<geometry> -->
    <!-- 	  <cylinder length="0.03" radius="${cyl_radius}" /> -->
    <!-- 	</geometry> -->
    <!-- 	<material name="green" /> -->
    <!-- </visual> -->
  </link>
  <link name="left_hand_e">
        </link>
  <!-- LENGTH NOT FOUND IN DATASHEET! GUESSED, BUT POSITION CALCULATED: E4 = D-G-F!!! -->
  <link name="left_hand_e4">
    <!-- <visual> -->
    <!-- 	<origin rpy="0 0 0" xyz="${side*(0.02825)} 0 0.043" /> -->
    <!-- 	<geometry> -->
    <!-- 	  <cylinder length="0.026" radius="${cyl_radius}" /> -->
    <!-- 	</geometry> -->
    <!-- 	<material name="green" /> -->
    <!-- </visual> -->
  </link>
  <!-- LENGTH NOT FOUND IN DATASHEET! GUESSED, BUT POSITION CALCULATED: E5 = D-G!!! -->
  <link name="left_hand_e5">
    <!-- <visual> -->
    <!-- 	<origin rpy="0 0 0" xyz="${side*(0.00675)} 0 0.04775" /> -->
    <!-- 	<geometry> -->
    <!-- 	  <cylinder length="0.0355" radius="${cyl_radius}" /> -->
    <!-- 	</geometry> -->
    <!-- 	<material name="green" /> -->
    <!-- </visual> -->
  </link>
  <!-- THUMB LINKS -->
  <link name="left_hand_z">
    <visual>
      <origin xyz="0 0 0.02442"/>
      <geometry>
        <mesh filename="package://schunk_lwa4p_svh/description/meshes/svh/d10.dae" scale="1 -1 1"/>
      </geometry>
    </visual>
    <collision>
      <origin xyz="0 0 0.02442"/>
      <geometry>
        <mesh filename="package://schunk_lwa4p_svh/description/meshes/svh/d10.dae" scale="1 -1 1"/>
      </geometry>
    </collision>
  </link>
  <link name="left_hand_virtual_a"/>
  <link name="left_hand_a">
    <visual>
      <geometry>
        <mesh filename="package://schunk_lwa4p_svh/description/meshes/svh/d11.dae" scale="1 -1 -1"/>
      </geometry>
    </visual>
    <collision>
      <geometry>
        <mesh filename="package://schunk_lwa4p_svh/description/meshes/svh/d11.dae" scale="1 -1 -1"/>
      </geometry>
    </collision>
  </link>
  <link name="left_hand_b">
    <visual>
      <geometry>
        <mesh filename="package://schunk_lwa4p_svh/description/meshes/svh/d12.dae" scale="1 -1 -1"/>
      </geometry>
    </visual>
    <collision>
      <geometry>
        <mesh filename="package://schunk_lwa4p_svh/description/meshes/svh/d12.dae" scale="1 -1 -1"/>
      </geometry>
    </collision>
  </link>
  <link name="left_hand_c">
    <visual>
      <geometry>
        <mesh filename="package://schunk_lwa4p_svh/description/meshes/svh/d13.dae" scale="1 -1 -1"/>
      </geometry>
    </visual>
    <collision>
      <geometry>
        <mesh filename="package://schunk_lwa4p_svh/description/meshes/svh/d13.dae" scale="1 -1 -1"/>
      </geometry>
    </collision>
  </link>
  <!-- INDEX FINGER LINKS -->
  <link name="left_hand_virtual_l">
    <visual>
      <origin xyz="0 0 0.01321"/>
      <geometry>
        <mesh filename="package://schunk_lwa4p_svh/description/meshes/svh/f10.dae"/>
      </geometry>
    </visual>
    <collision>
      <origin xyz="0 0 0.01321"/>
      <geometry>
        <mesh filename="package://schunk_lwa4p_svh/description/meshes/svh/f10.dae"/>
      </geometry>
    </collision>
  </link>
  <link name="left_hand_l">
    <visual>
      <geometry>
        <mesh filename="package://schunk_lwa4p_svh/description/meshes/svh/f11.dae"/>
      </geometry>
    </visual>
    <collision>
      <geometry>
        <mesh filename="package://schunk_lwa4p_svh/description/meshes/svh/f11.dae"/>
      </geometry>
    </collision>
  </link>
  <link name="left_hand_p">
    <visual>
      <geometry>
        <mesh filename="package://schunk_lwa4p_svh/description/meshes/svh/f12.dae"/>
      </geometry>
    </visual>
    <collision>
      <geometry>
        <mesh filename="package://schunk_lwa4p_svh/description/meshes/svh/f12.dae"/>
      </geometry>
    </collision>
  </link>
  <link name="left_hand_t">
    <visual>
      <geometry>
        <mesh filename="package://schunk_lwa4p_svh/description/meshes/svh/f13.dae"/>
      </geometry>
    </visual>
    <collision>
      <geometry>
        <mesh filename="package://schunk_lwa4p_svh/description/meshes/svh/f13.dae"/>
      </geometry>
    </collision>
  </link>
  <!-- MIDDLE FINGER LINKS -->
  <link name="left_hand_virtual_k">
    <visual>
      <origin xyz="0 0 0.01321"/>
      <geometry>
        <mesh filename="package://schunk_lwa4p_svh/description/meshes/svh/f20.dae"/>
      </geometry>
    </visual>
    <collision>
      <origin xyz="0 0 0.01321"/>
      <geometry>
        <mesh filename="package://schunk_lwa4p_svh/description/meshes/svh/f20.dae"/>
      </geometry>
    </collision>
  </link>
  <link name="left_hand_k">
    <visual>
      <geometry>
        <mesh filename="package://schunk_lwa4p_svh/description/meshes/svh/f21.dae"/>
      </geometry>
    </visual>
    <collision>
      <geometry>
        <mesh filename="package://schunk_lwa4p_svh/description/meshes/svh/f21.dae"/>
      </geometry>
    </collision>
  </link>
  <link name="left_hand_o">
    <visual>
      <geometry>
        <mesh filename="package://schunk_lwa4p_svh/description/meshes/svh/f22.dae"/>
      </geometry>
    </visual>
    <collision>
      <geometry>
        <mesh filename="package://schunk_lwa4p_svh/description/meshes/svh/f22.dae"/>
      </geometry>
    </collision>
  </link>
  <link name="left_hand_s">
    <visual>
      <geometry>
        <mesh filename="package://schunk_lwa4p_svh/description/meshes/svh/f23.dae"/>
      </geometry>
    </visual>
    <collision>
      <geometry>
        <mesh filename="package://schunk_lwa4p_svh/description/meshes/svh/f23.dae"/>
      </geometry>
    </collision>
  </link>
  <!-- RING FINGER LINKS -->
  <link name="left_hand_virtual_j">
    <visual>
      <origin xyz="0 0 -0.01321"/>
      <geometry>
        <mesh filename="package://schunk_lwa4p_svh/description/meshes/svh/f30.dae"/>
      </geometry>
    </visual>
    <collision>
      <origin xyz="0 0 -0.01321"/>
      <geometry>
        <mesh filename="package://schunk_lwa4p_svh/description/meshes/svh/f30.dae"/>
      </geometry>
    </collision>
  </link>
  <link name="left_hand_j">
    <visual>
      <geometry>
        <mesh filename="package://schunk_lwa4p_svh/description/meshes/svh/f31.dae"/>
      </geometry>
    </visual>
    <collision>
      <geometry>
        <mesh filename="package://schunk_lwa4p_svh/description/meshes/svh/f31.dae"/>
      </geometry>
    </collision>
  </link>
  <link name="left_hand_n">
    <visual>
      <geometry>
        <mesh filename="package://schunk_lwa4p_svh/description/meshes/svh/f32.dae"/>
      </geometry>
    </visual>
    <collision>
      <geometry>
        <mesh filename="package://schunk_lwa4p_svh/description/meshes/svh/f32.dae"/>
      </geometry>
    </collision>
  </link>
  <link name="left_hand_r">
    <visual>
      <geometry>
        <mesh filename="package://schunk_lwa4p_svh/description/meshes/svh/f33.dae"/>
      </geometry>
    </visual>
    <collision>
      <geometry>
        <mesh filename="package://schunk_lwa4p_svh/description/meshes/svh/f33.dae"/>
      </geometry>
    </collision>
  </link>
  <!-- LITTLE FINGER LINKS -->
  <link name="left_hand_virtual_i">
    <visual>
      <origin xyz="0 0 -0.01321"/>
      <geometry>
        <mesh filename="package://schunk_lwa4p_svh/description/meshes/svh/f40.dae"/>
      </geometry>
    </visual>
    <collision>
      <origin xyz="0 0 -0.01321"/>
      <geometry>
        <mesh filename="package://schunk_lwa4p_svh/description/meshes/svh/f40.dae"/>
      </geometry>
    </collision>
  </link>
  <link name="left_hand_i">
    <visual>
      <geometry>
        <mesh filename="package://schunk_lwa4p_svh/description/meshes/svh/f41.dae"/>
      </geometry>
    </visual>
    <collision>
      <geometry>
        <mesh filename="package://schunk_lwa4p_svh/description/meshes/svh/f41.dae"/>
      </geometry>
    </collision>
  </link>
  <link name="left_hand_m">
    <visual>
      <geometry>
        <mesh filename="package://schunk_lwa4p_svh/description/meshes/svh/f42.dae"/>
      </geometry>
    </visual>
    <collision>
      <geometry>
        <mesh filename="package://schunk_lwa4p_svh/description/meshes/svh/f42.dae"/>
      </geometry>
    </collision>
  </link>
  <link name="left_hand_q">
    <visual>
      <geometry>
        <mesh filename="package://schunk_lwa4p_svh/description/meshes/svh/f43.dae"/>
      </geometry>
    </visual>
    <collision>
      <geometry>
        <mesh filename="package://schunk_lwa4p_svh/description/meshes/svh/f43.dae"/>
      </geometry>
    </collision>
  </link>
  <joint name="left_hand_Thumb_Flexion" type="revolute">
    <parent link="left_hand_virtual_a"/>
    <child link="left_hand_a"/>
    <limit effort="1000.0" lower="0.0" upper="0.9704" velocity="1"/>
    <origin rpy="0 0 0.9704" xyz="0 0 0"/>
    <axis xyz="0 0 -1"/>
  </joint>
  <joint name="left_hand_Thumb_Helper" type="fixed">
    <parent link="left_hand_z"/>
    <child link="left_hand_virtual_a"/>
    <origin rpy="0 -1.5707 3.1416" xyz="0 0 0.04596"/>
  </joint>
  <!-- BASE_LINE JOINTS -->
  <joint name="left_hand_Thumb_Opposition" type="revolute">
    <parent link="left_hand_e1"/>
    <child link="left_hand_z"/>
    <limit effort="1000.0" lower="0.0" upper="0.9879" velocity="1"/>
    <origin rpy="0 0.2618 1.571" xyz="0.0169 0.02626 0"/>
    <axis xyz="0 0 1"/>
  </joint>
  <!-- JOINT NOT FOR BASE_LINE. BUT WRITTEN DOWN HERE FOR BETTER UX -->
  <joint name="left_hand_f1" type="fixed">
    <parent link="left_hand_e1"/>
    <child link="left_hand_d"/>
    <origin rpy="0 0 0" xyz="0 0 0"/>
  </joint>
  <joint name="left_hand_f2" type="fixed">
    <parent link="left_hand_d"/>
    <child link="left_hand_h"/>
    <origin rpy="0 0 0" xyz="0 0 0"/>
  </joint>
  <joint name="left_hand_f3" type="fixed">
    <parent link="left_hand_h"/>
    <child link="left_hand_d2"/>
    <origin rpy="0 0 0" xyz="0 0 0"/>
  </joint>
  <joint name="left_hand_f4" type="fixed">
    <parent link="left_hand_base_link"/>
    <child link="left_hand_e1"/>
    <origin rpy="0 0 0" xyz="0 -0.01313 0"/>
  </joint>
  <joint name="left_hand_j5" type="revolute">
    <parent link="left_hand_e1"/>
    <child link="left_hand_e2"/>
    <limit effort="1000.0" lower="0.0" upper="0.98786" velocity="1"/>
    <origin rpy="0 0 0" xyz="-0.0184 0.006 0.0375"/>
    <axis xyz="0 0 -1"/>
    <mimic joint="left_hand_Thumb_Opposition" multiplier="1" offset="0"/>
  </joint>
  <joint name="left_hand_f5" type="fixed">
    <parent link="left_hand_e2"/>
    <child link="left_hand_e3"/>
    <origin rpy="0 0 0" xyz="0 -0.0060 0"/>
  </joint>
  <joint name="left_hand_f6" type="fixed">
    <parent link="left_hand_e3"/>
    <child link="left_hand_e"/>
    <origin rpy="0 0 0" xyz="0 0 0"/>
  </joint>
  <joint name="left_hand_f7" type="fixed">
    <parent link="left_hand_e"/>
    <child link="left_hand_e4"/>
    <origin rpy="0 0 0" xyz="0 0 0"/>
  </joint>
  <joint name="left_hand_f8" type="fixed">
    <parent link="left_hand_e"/>
    <child link="left_hand_e5"/>
    <origin rpy="0 0 0" xyz="0 0 0"/>
  </joint>
  <!-- THUMB JOINTS -->
  <joint name="left_hand_j3" type="revolute">
    <parent link="left_hand_a"/>
    <child link="left_hand_b"/>
    <limit effort="1000.0" lower="0.0" upper="0.98506" velocity="1"/>
    <origin rpy="0 0 0" xyz="0.0485 0 0"/>
    <axis xyz="0 0 -1"/>
    <mimic joint="left_hand_Thumb_Flexion" multiplier="1.01511" offset="0"/>
  </joint>
  <joint name="left_hand_j4" type="revolute">
    <parent link="left_hand_b"/>
    <child link="left_hand_c"/>
    <limit effort="1000.0" lower="0.0" upper="1.406" velocity="1"/>
    <origin rpy="0 0 0" xyz="0.030 0 0"/>
    <axis xyz="0 0 -1"/>
    <mimic joint="left_hand_Thumb_Flexion" multiplier="1.44889" offset="0"/>
  </joint>
  <!-- INDEX FINGER JOINTS -->
  <joint name="left_hand_Index_Finger_Distal" type="revolute">
    <parent link="left_hand_l"/>
    <child link="left_hand_p"/>
    <limit effort="1000.0" lower="0" upper="1.334" velocity="1"/>
    <origin rpy="0 0 0" xyz="0.04804 0 0"/>
    <axis xyz="0 0 1"/>
  </joint>
  <joint name="left_hand_Index_Finger_Proximal" type="revolute">
    <parent link="left_hand_virtual_l"/>
    <child link="left_hand_l"/>
    <limit effort="1000.0" lower="0.0" upper="0.79849" velocity="1"/>
    <origin rpy="-1.5707 0 0" xyz="0 0 0"/>
    <axis xyz="0 0 1"/>
  </joint>
  <!-- JOINT Finger_Spread in BASE_LINE section for better UX -->
  <joint name="left_hand_j14" type="revolute">
    <parent link="left_hand_p"/>
    <child link="left_hand_t"/>
    <limit effort="1000.0" lower="0" upper="1.394" velocity="1"/>
    <origin rpy="0 0 0" xyz="0.026 0 0"/>
    <axis xyz="0 0 1"/>
    <mimic joint="left_hand_Index_Finger_Distal" multiplier="1.0450" offset="0"/>
  </joint>
  <!-- MIDDLE FINGER JOINTS -->
  <joint name="left_hand_Middle_Finger_Proximal" type="revolute">
    <parent link="left_hand_virtual_k"/>
    <child link="left_hand_k"/>
    <limit effort="1000.0" lower="0.0" upper="0.79849" velocity="1"/>
    <origin rpy="-1.5707 0 0" xyz="0 0 0"/>
    <axis xyz="0 0 1"/>
  </joint>
  <joint name="left_hand_Middle_Finger_Distal" type="revolute">
    <parent link="left_hand_k"/>
    <child link="left_hand_o"/>
    <limit effort="1000.0" lower="0" upper="1.334" velocity="1"/>
    <origin rpy="0 0 0" xyz="0.05004 0 0"/>
    <axis xyz="0 0 1"/>
  </joint>
  <joint name="left_hand_j15" type="revolute">
    <parent link="left_hand_o"/>
    <child link="left_hand_s"/>
    <limit effort="1000.0" lower="0" upper="1.334" velocity="1"/>
    <origin rpy="0 0 0" xyz="0.032 0 0"/>
    <axis xyz="0 0 1"/>
    <mimic joint="left_hand_Middle_Finger_Distal" multiplier="1.0454" offset="0"/>
  </joint>
  <!-- RING FINGER JOINTS -->
  <joint name="left_hand_Ring_Finger" type="revolute">
    <parent link="left_hand_virtual_j"/>
    <child link="left_hand_j"/>
    <limit effort="1000.0" lower="0.0" upper="0.98175" velocity="1"/>
    <origin rpy="1.5707 0 0" xyz="0 0 0"/>
    <axis xyz="0 0 1"/>
  </joint>
  <joint name="left_hand_j12" type="revolute">
    <parent link="left_hand_j"/>
    <child link="left_hand_n"/>
    <limit effort="1000.0" lower="0" upper="1.334" velocity="1"/>
    <origin rpy="0 0 0" xyz="0.05004 0 0"/>
    <axis xyz="0 0 1"/>
    <mimic joint="left_hand_Ring_Finger" multiplier="1.3588" offset="0"/>
  </joint>
  <joint name="left_hand_j16" type="revolute">
    <parent link="left_hand_n"/>
    <child link="left_hand_r"/>
    <limit effort="1000.0" lower="0" upper="1.395" velocity="1"/>
    <origin rpy="0 0 0" xyz="0.032 0 0"/>
    <axis xyz="0 0 1"/>
    <mimic joint="left_hand_Ring_Finger" multiplier="1.42093" offset="0"/>
  </joint>
  <!-- PINKY JOINTS -->
  <joint name="left_hand_Pinky" type="revolute">
    <parent link="left_hand_virtual_i"/>
    <child link="left_hand_i"/>
    <limit effort="1000.0" lower="0.0" upper="0.98175" velocity="1"/>
    <origin rpy="1.5707 0 0" xyz="0 0 0"/>
    <axis xyz="0 0 1"/>
  </joint>
  <joint name="left_hand_j13" type="revolute">
    <parent link="left_hand_i"/>
    <child link="left_hand_m"/>
    <limit effort="1000.0" lower="0" upper="1.334" velocity="1"/>
    <origin rpy="0 0 0" xyz="0.04454 0 0"/>
    <axis xyz="0 0 1"/>
    <mimic joint="left_hand_Pinky" multiplier="1.35880" offset="0"/>
  </joint>
  <joint name="left_hand_j17" type="revolute">
    <parent link="left_hand_m"/>
    <child link="left_hand_q"/>
    <limit effort="1000.0" lower="0" upper="1.3971" velocity="1"/>
    <origin rpy="0 0 0" xyz="0.022 0 0"/>
    <axis xyz="0 0 1"/>
    <mimic joint="left_hand_Pinky" multiplier="1.42307" offset="0"/>
  </joint>
  <joint name="left_hand_index_spread" type="revolute">
    <parent link="left_hand_d2"/>
    <child link="left_hand_virtual_l"/>
    <limit effort="1000.0" lower="0.0" upper="0.28833" velocity="1"/>
    <origin rpy="0 -1.5707 1.5707" xyz="0.025 0 0.110"/>
    <axis xyz="0 0 -1"/>
    <mimic joint="left_hand_Finger_Spread" multiplier="0.5" offset="0"/>
  </joint>
  <joint name="left_hand_middle_spread_dummy" type="fixed">
    <parent link="left_hand_d"/>
    <child link="left_hand_virtual_k"/>
    <origin rpy="0 -1.5707 1.5707" xyz="0 0 0.110"/>
  </joint>
  <joint name="left_hand_ring_spread" type="revolute">
    <parent link="left_hand_e5"/>
    <child link="left_hand_virtual_j"/>
    <limit effort="1000.0" lower="0.0" upper="0.28833" velocity="1"/>
    <origin rpy="-1.5707 -1.5707 0" xyz="-0.003855 0 0.0655"/>
    <axis xyz="0 0 -1"/>
    <mimic joint="left_hand_Finger_Spread" multiplier="0.5" offset="0"/>
  </joint>
  <joint name="left_hand_Finger_Spread" type="revolute">
    <parent link="left_hand_e4"/>
    <child link="left_hand_virtual_i"/>
    <limit effort="1000.0" lower="0.0" upper="0.5829" velocity="1"/>
    <origin rpy="-1.5707 -1.5707 0" xyz="-0.025355 0 0.056"/>
    <axis xyz="0 0 -1"/>
  </joint>
  <!-- extensions -->
  <!--xacro:svh_transmission name="${name}" /-->
  <transmission name="left_hand_Finger_Spread_trans">
    <type>transmission_interface/SimpleTransmission</type>
    <joint name="left_hand_Finger_Spread">
      <hardwareInterface>PositionJointInterface</hardwareInterface>
      <hardwareInterface>VelocityJointInterface</hardwareInterface>
      <hardwareInterface>EffortJointInterface</hardwareInterface>
    </joint>
    <actuator name="left_hand_Finger_Spread_motor">
      <mechanicalReduction>1</mechanicalReduction>
    </actuator>
  </transmission>
  <transmission name="left_hand_Pinky_trans">
    <type>transmission_interface/SimpleTransmission</type>
    <joint name="left_hand_Pinky">
      <hardwareInterface>PositionJointInterface</hardwareInterface>
      <hardwareInterface>VelocityJointInterface</hardwareInterface>
      <hardwareInterface>EffortJointInterface</hardwareInterface>
    </joint>
    <actuator name="left_hand_Pinky_motor">
      <mechanicalReduction>1</mechanicalReduction>
    </actuator>
  </transmission>
  <transmission name="left_hand_Ring_Finger_trans">
    <type>transmission_interface/SimpleTransmission</type>
    <joint name="left_hand_Ring_Finger">
      <hardwareInterface>PositionJointInterface</hardwareInterface>
      <hardwareInterface>VelocityJointInterface</hardwareInterface>
      <hardwareInterface>EffortJointInterface</hardwareInterface>
    </joint>
    <actuator name="left_hand_Ring_Finger_motor">
      <mechanicalReduction>1</mechanicalReduction>
    </actuator>
  </transmission>
  <transmission name="left_hand_Middle_Finger_Proximal_trans">
    <type>transmission_interface/SimpleTransmission</type>
    <joint name="left_hand_Middle_Finger_Proximal">
      <hardwareInterface>PositionJointInterface</hardwareInterface>
      <hardwareInterface>VelocityJointInterface</hardwareInterface>
      <hardwareInterface>EffortJointInterface</hardwareInterface>
    </joint>
    <actuator name="left_hand_Middle_Finger_Proximal_motor">
      <mechanicalReduction>1</mechanicalReduction>
    </actuator>
  </transmission>
  <transmission name="left_hand_Middle_Finger_Distal_trans">
    <type>transmission_interface/SimpleTransmission</type>
    <joint name="left_hand_Middle_Finger_Distal">
      <hardwareInterface>PositionJointInterface</hardwareInterface>
      <hardwareInterface>VelocityJointInterface</hardwareInterface>
      <hardwareInterface>EffortJointInterface</hardwareInterface>
    </joint>
    <actuator name="left_hand_Middle_Finger_Distal_motor">
      <mechanicalReduction>1</mechanicalReduction>
    </actuator>
  </transmission>
  <transmission name="left_hand_Index_Finger_Proximal_trans">
    <type>transmission_interface/SimpleTransmission</type>
    <joint name="left_hand_Index_Finger_Proximal">
      <hardwareInterface>PositionJointInterface</hardwareInterface>
      <hardwareInterface>VelocityJointInterface</hardwareInterface>
      <hardwareInterface>EffortJointInterface</hardwareInterface>
    </joint>
    <actuator name="left_hand_Index_Finger_Proximal_motor">
      <mechanicalReduction>1</mechanicalReduction>
    </actuator>
  </transmission>
  <transmission name="left_hand_Index_Finger_Distal_trans">
    <type>transmission_interface/SimpleTransmission</type>
    <joint name="left_hand_Index_Finger_Distal">
      <hardwareInterface>PositionJointInterface</hardwareInterface>
      <hardwareInterface>VelocityJointInterface</hardwareInterface>
      <hardwareInterface>EffortJointInterface</hardwareInterface>
    </joint>
    <actuator name="left_hand_Index_Finger_Distal_motor">
      <mechanicalReduction>1</mechanicalReduction>
    </actuator>
  </transmission>
  <transmission name="left_hand_Thumb_Flexion_trans">
    <type>transmission_interface/SimpleTransmission</type>
    <joint name="left_hand_Thumb_Flexion">
      <hardwareInterface>PositionJointInterface</hardwareInterface>
      <hardwareInterface>VelocityJointInterface</hardwareInterface>
      <hardwareInterface>EffortJointInterface</hardwareInterface>
    </joint>
    <actuator name="left_hand_Thumb_Flexion_motor">
      <mechanicalReduction>1</mechanicalReduction>
    </actuator>
  </transmission>
  <transmission name="left_hand_Thumb_Opposition_trans">
    <type>transmission_interface/SimpleTransmission</type>
    <joint name="left_hand_Thumb_Opposition">
      <hardwareInterface>PositionJointInterface</hardwareInterface>
      <hardwareInterface>VelocityJointInterface</hardwareInterface>
      <hardwareInterface>EffortJointInterface</hardwareInterface>
    </joint>
    <actuator name="left_hand_Thumb_Opposition_motor">
      <mechanicalReduction>1</mechanicalReduction>
    </actuator>
  </transmission>
  <!-- ros_control plugin -->
  <gazebo>
    <plugin filename="libhwi_switch_gazebo_ros_control.so" name="ros_control">
      <robotNamespace>left_hand</robotNamespace>
      <filterJointsParam>joint_names</filterJointsParam>
    </plugin>
  </gazebo>
  <joint name="base_joint" type="fixed">
    <parent link="world"/>
    <child link="body"/>
  </joint>
  <joint name="camera_joint" type="fixed">
    <parent link="head"/>
    <child link="zed_base_link"/>
    <origin rpy="0 0 -1.5707" xyz=".155 0.03 1.14"/>
  </joint>
  <!-- base_link -->
  <link name="zed_base_link"/>
  <link name="zed_depth_frame"/>
  <!-- Camera Center -->
  <joint name="zed_camera_center_joint" type="fixed">
    <parent link="zed_base_link"/>
    <child link="zed_camera_center"/>
    <origin rpy="0 0 0" xyz="0 0 0"/>
  </joint>
  <link name="zed_camera_center">
    <visual>
      <origin rpy="0 0 0" xyz="0 0 0"/>
      <geometry>
        <mesh filename="package://grasping_sim/urdf/urdf/zed/models/ZED.stl"/>
      </geometry>
      <material name="light_grey">
        <color rgba="0.8 0.8 0.8 0.8"/>
      </material>
    </visual>
  </link>
  <!-- Left Camera -->
  <joint name="zed_left_camera_joint" type="fixed">
    <parent link="zed_camera_center"/>
    <child link="zed_left_camera_frame"/>
    <origin rpy="0 0 0" xyz="0 0.06 0"/>
  </joint>
  <link name="zed_left_camera_frame"/>
  <joint name="zed_left_camera_depth_joint" type="fixed">
    <origin rpy="-1.5707 1.5707 -1.5707" xyz="0.05 0.05 0.05"/>
    <parent link="zed_left_camera_frame"/>
    <child link="zed_depth_frame"/>
  </joint>
  <joint name="zed_left_camera_optical_joint" type="fixed">
    <origin rpy="-1.57079632679 0.0 -1.57079632679" xyz="0 0 0"/>
    <parent link="zed_left_camera_frame"/>
    <child link="zed_left_camera_optical_frame"/>
  </joint>
  <link name="zed_left_camera_optical_frame"/>
  <!-- Right Camera -->
  <joint name="zed_right_camera_joint" type="fixed">
    <parent link="zed_camera_center"/>
    <child link="zed_right_camera_frame"/>
    <origin rpy="0 0 0" xyz="0 -0.06 0"/>
  </joint>
  <link name="zed_right_camera_frame"/>
  <joint name="zed_right_camera_optical_joint" type="fixed">
    <origin rpy="-1.57079632679 0.0 -1.57079632679" xyz="0 0 0"/>
    <parent link="zed_right_camera_frame"/>
    <child link="zed_right_camera_optical_frame"/>
  </joint>
  <link name="zed_right_camera_optical_frame"/>
  <!-- camera -->
  <gazebo reference="zed_left_camera_frame">
    <sensor name="camera1" type="camera">
      <update_rate>15.0</update_rate>
      <camera name="head">
        <pose>0.005 0 0 0 0 0</pose>
        <horizontal_fov>1.3962634</horizontal_fov>
        <image>
          <width>400</width>
          <height>400</height>
          <format>R8G8B8</format>
        </image>
        <clip>
          <near>0.01</near>
          <far>100</far>
        </clip>
        <noise>
          <type>gaussian</type>
          <stddev>0.007</stddev>
        </noise>
      </camera>
      <plugin filename="libgazebo_ros_camera.so" name="camera_controller">
        <alwaysOn>true</alwaysOn>
        <updateRate>0.0</updateRate>
        <cameraName>/zed/zed_node/left/</cameraName>
        <imageTopicName>image_rect_color</imageTopicName>
        <cameraInfoTopicName>camera_info</cameraInfoTopicName>
        <frameName>zed_left_camera_frame</frameName>
        <hackBaseline>0.07</hackBaseline>
        <distortionK1>0.0</distortionK1>
        <distortionK2>0.0</distortionK2>
        <distortionK3>0.0</distortionK3>
        <distortionT1>0.0</distortionT1>
        <distortionT2>0.0</distortionT2>
      </plugin>
    </sensor>
  </gazebo>
  <link name="camera_foot_link">
    <inertial>
      <mass value="0.0005"/>
      <origin rpy="0 0 0" xyz="0 0 0"/>
      <inertia ixx="0.0001" ixy="0" ixz="0" iyy="0.0001" iyz="0" izz="0.0001"/>
    </inertial>
    <!--      <visual>-->
    <!--        <origin xyz="0.01 0 0" rpy="${M_PI/2} 0 ${M_PI/2}" />-->
    <!--        <geometry>-->
    <!--           <mesh filename="package://luh_youbot_description/meshes/sensors/asus_xtion_pro_live_base.dae" scale="0.0004 0.0007 0.001"/>-->
    <!--        </geometry>-->
    <!--        <material name="Black" />-->
    <!--      </visual>-->
    <!--      <collision>-->
    <!--        <origin xyz="0.01 0 0" rpy="${M_PI/2} 0 ${M_PI/2}" />-->
    <!--        <geometry>-->
    <!--           <mesh filename="package://luh_youbot_description/meshes/sensors/asus_xtion_pro_live_base.dae" scale="0.0004 0.0007 0.001"/>-->
    <!--        </geometry>-->
    <!--      </collision >-->
  </link>
  <joint name="camera_foot_joint" type="fixed">
    <origin rpy="0 -1.5707 0" xyz="0.08 -0.04 -0.05"/>
    <parent link="zed_depth_frame"/>
    <child link="camera_foot_link"/>
  </joint>
  <link name="camera_tilt_link">
    <inertial>
      <mass value="0.0001"/>
      <origin rpy="0 0 0" xyz="0 0 0"/>
      <inertia ixx="0.0001" ixy="0" ixz="0" iyy="0.0001" iyz="0" izz="0.0001"/>
    </inertial>
    <!--      <visual>-->
    <!--        <origin xyz="0 0 0.0075" rpy="0 0 0" />-->
    <!--        <geometry>-->
    <!--          <cylinder length="0.025" radius="0.005" />-->
    <!--        </geometry>-->
    <!--        <material name="Black" />-->
    <!--      </visual>-->
    <!--      <collision>-->
    <!--        <origin xyz="0 0 0.0075" rpy="0 0 0" />-->
    <!--        <geometry>-->
    <!--          <cylinder length="0.025" radius="0.005" />-->
    <!--        </geometry>-->
    <!--        <material name="Black" />-->
    <!--      </collision >-->
  </link>
  <joint name="asus_xtion_tilt_joint" type="fixed">
    <parent link="camera_foot_link"/>
    <child link="camera_tilt_link"/>
    <!--<axis xyz="0 1 0"/>-->
    <origin rpy="0 0.0 0" xyz="0 0 0.0075"/>
    <!--<limit effort="100" lower="-0.541052068" upper="0.541052068" velocity="1.0"/>-->
  </joint>
  <link name="camera_camera">
    <inertial>
      <mass value="0.001"/>
      <origin rpy="0 0 0" xyz="0 0 0"/>
      <inertia ixx="0.0001" ixy="0" ixz="0" iyy="0.0001" iyz="0" izz="0.0001"/>
    </inertial>
    <!--      <visual>-->
    <!--        <origin xyz="0.02 -0.03 0" rpy="${M_PI/2} 0 ${M_PI/2}" />-->
    <!--        <geometry>-->
    <!--          <mesh filename="package://luh_youbot_description/meshes/sensors/asus_xtion_pro_live_camera.dae" scale="0.001 0.001 0.001"/>-->
    <!--        </geometry>-->
    <!--        <material name="Black" />-->
    <!--      </visual>-->
    <!--      <collision>-->
    <!--        <origin xyz="0.02 -0.03 0" rpy="${M_PI/2} 0 ${M_PI/2}" />-->
    <!--        <geometry>-->
    <!--           <mesh filename="package://luh_youbot_description/meshes/sensors/asus_xtion_pro_live_camera.dae" scale="0.001 0.001 0.001"/>-->
    <!--        </geometry>-->
    <!--      </collision >-->
  </link>
  <joint name="camera_camera_joint" type="fixed">
    <origin rpy="0 0 0" xyz="0 0.03 0.03"/>
    <parent link="camera_tilt_link"/>
    <child link="camera_camera"/>
  </joint>
  <link name="camera_depth_frame">
    <inertial>
      <mass value="0.0001"/>
      <origin xyz="0 0 0"/>
      <inertia ixx="0.1" ixy="0" ixz="0" iyy="0.1" iyz="0" izz="0.1"/>
    </inertial>
  </link>
  <joint name="camera_depth_joint" type="fixed">
    <parent link="camera_camera"/>
    <child link="camera_depth_frame"/>
    <origin rpy="0 0 0" xyz="0.03 0.015 0"/>
  </joint>
  <link name="camera_depth_optical_frame">
    <inertial>
      <mass value="0.0001"/>
      <origin xyz="0 0 0"/>
      <inertia ixx="0.1" ixy="0" ixz="0" iyy="0.1" iyz="0" izz="0.1"/>
    </inertial>
  </link>
  <joint name="camera_depth_optical_joint" type="fixed">
    <parent link="camera_camera"/>
    <child link="camera_depth_optical_frame"/>
    <origin rpy="-1.57079632679 0 -1.57079632679" xyz="0.03 0.015 0"/>
  </joint>
  <link name="camera_rgb_frame">
    <inertial>
      <mass value="0.0001"/>
      <origin xyz="0 0 0"/>
      <inertia ixx="0.1" ixy="0" ixz="0" iyy="0.1" iyz="0" izz="0.1"/>
    </inertial>
  </link>
  <joint name="camera_rgb_joint" type="fixed">
    <parent link="camera_camera"/>
    <child link="camera_rgb_frame"/>
    <origin rpy="0 0 0" xyz="0.03 -0.005 0"/>
  </joint>
  <link name="camera_rgb_optical_frame">
    <inertial>
      <mass value="0.0001"/>
      <origin xyz="0 0 0"/>
      <inertia ixx="0.1" ixy="0" ixz="0" iyy="0.1" iyz="0" izz="0.1"/>
    </inertial>
  </link>
  <joint name="camera_rgb_optical_joint" type="fixed">
    <parent link="camera_camera"/>
    <child link="camera_rgb_optical_frame"/>
    <origin rpy="-1.57079632679 0 -1.57079632679" xyz="0.03 -0.005 0"/>
  </joint>
  <link name="camera_laser_frame">
    <inertial>
      <mass value="0.0001"/>
      <origin xyz="0 0 0"/>
      <inertia ixx="0.1" ixy="0" ixz="0" iyy="0.1" iyz="0" izz="0.1"/>
    </inertial>
  </link>
  <joint name="camera_laser_joint" type="fixed">
    <parent link="camera_camera"/>
    <child link="camera_laser_frame"/>
    <origin rpy="0 0 0" xyz="0.03 -0.055 0"/>
  </joint>
  <link name="camera_laser_optical_frame">
    <inertial>
      <mass value="0.0001"/>
      <origin xyz="0 0 0"/>
      <inertia ixx="0.1" ixy="0" ixz="0" iyy="0.1" iyz="0" izz="0.1"/>
    </inertial>
  </link>
  <joint name="camera_laser_optical_joint" type="fixed">
    <parent link="camera_camera"/>
    <child link="camera_laser_optical_frame"/>
    <origin rpy="1.57079632679 0 -1.57079632679" xyz="0.03 -0.055 0"/>
  </joint>
  <gazebo reference="camera_camera">
    <sensor name="camera_depth_frame_sensor" type="depth">
      <always_on>true</always_on>
      <update_rate>10.0</update_rate>
      <camera>
        <horizontal_fov>1.53588974176</horizontal_fov>
        <image>
          <format>R8G8B8</format>
          <width>640</width>
          <height>480</height>
        </image>
        <clip>
          <near>0.005</near>
          <far>3</far>
        </clip>
      </camera>
      <plugin filename="libgazebo_ros_openni_kinect.so" name="camera_depth_frame_controller">
        <baseline>0.2</baseline>
        <alwaysOn>true</alwaysOn>
        <updateRate>10.0</updateRate>
        <cameraName>camera_depth</cameraName>
        <cameraName>camera_rgb</cameraName>
        <imageTopicName>/camera/rgb/image_raw</imageTopicName>
        <cameraInfoTopicName>/camera/rgb/camera_info</cameraInfoTopicName>
        <!--imageTopicName>/${name}/ir/image_raw</imageTopicName>
      <cameraInfoTopicName>/${name}/ir/camera_info</cameraInfoTopicName-->
        <depthImageTopicName>/camera/depth/image_raw</depthImageTopicName>
        <depthImageCameraInfoTopicName>/camera/depth/camera_info</depthImageCameraInfoTopicName>
        <pointCloudTopicName>/zed/zed_node/point_cloud/cloud_registered</pointCloudTopicName>
        <frameName>camera_depth_optical_frame</frameName>
        <pointCloudCutoff>0.1</pointCloudCutoff>
        <distortionK1>0.00000001</distortionK1>
        <distortionK2>0.00000001</distortionK2>
        <distortionK3>0.00000001</distortionK3>
        <distortionT1>0.00000001</distortionT1>
        <distortionT2>0.00000001</distortionT2>
        <CxPrime>0</CxPrime>
        <Cx>0</Cx>
        <Cy>0</Cy>
        <focalLength>0</focalLength>
        <hackBaseline>0</hackBaseline>
      </plugin>
    </sensor>
    <!--
  <sensor type="depth" name="${name}_rgb_frame_sensor">    
    <always_on>true</always_on>
    <update_rate>20.0</update_rate>
    <camera>
      <horizontal_fov>${57.0*M_PI/180.0}</horizontal_fov>
      <image>
        <format>R8G8B8</format>
        <width>640</width>
        <height>480</height>
      </image>
      <clip>
        <near>0.1</near>
        <far>5</far>
      </clip>
    </camera>
    <plugin name="${name}_rgb_frame_controller" filename="libgazebo_ros_openni_kinect.so">
      <baseline>0.2</baseline>
      <alwaysOn>true</alwaysOn>
      <updateRate>20.0</updateRate>
      <cameraName>${name}_rgb</cameraName>
      <imageTopicName>/${name}/rgb/image_raw</imageTopicName>
      <cameraInfoTopicName>/${name}/rgb/camera_info</cameraInfoTopicName>
      <depthImageTopicName>/${name}/depth_registered/image_raw</depthImageTopicName>
      <depthImageCameraInfoTopicName>/${name}/depth_registered/camera_info</depthImageCameraInfoTopicName>
      <pointCloudTopicName>/${name}/depth_registered/points</pointCloudTopicName>
      <frameName>${name}_rgb_optical_frame</frameName>
      <pointCloudCutoff>0.5</pointCloudCutoff>
      <distortionK1>0.00000001</distortionK1>
      <distortionK2>0.00000001</distortionK2>
      <distortionK3>0.00000001</distortionK3>
      <distortionT1>0.00000001</distortionT1>
      <distortionT2>0.00000001</distortionT2>
      <CxPrime>0</CxPrime>
      <Cx>0</Cx>
      <Cy>0</Cy>
      <focalLength>0</focalLength>
      <hackBaseline>0</hackBaseline>
    </plugin>
  </sensor>
-->
  </gazebo>
</robot>

